<?xml version="1.0" ?>
<sdf version="1.9">
  <model name="simple_robot_4w" canonical_link="chassis">
    <pose>0 0 0 0 0 0</pose>

    <link name="chassis">
      <pose relative_to="__model__">0.05 0 0.04 0 0 0</pose>
      <inertial>
        <mass>1</mass>
        <inertia>
          <ixx>0.001191615</ixx><ixy>0</ixy><ixz>0</ixz>
          <iyy>0.004051490</iyy><iyz>0</iyz><izz>0.004766458</izz>
        </inertia>
      </inertial>
      <visual name="visual">
        <geometry><box><size>0.2 0.1 0.05</size></box></geometry>
        <material>
          <ambient>0.0 0.612 0.867 1</ambient>
          <diffuse>0.0 0.612 0.867 1</diffuse>
          <specular>0.0 0.612 0.867 1</specular>
        </material>
      </visual>
      <collision name="collision">
        <geometry><box><size>0.2 0.1 0.05</size></box></geometry>
      </collision>
    </link>

    <link name="left_front_wheel">
      <pose relative_to="chassis">0.06 0.06 0 -1.5707 0 0</pose>
      <inertial>
        <mass>0.2</mass>
        <inertia>
          <ixx>0.000800</ixx><ixy>0</ixy><ixz>0</ixz>
          <iyy>0.000433</iyy><iyz>0</iyz><izz>0.000433</izz>
        </inertia>
      </inertial>
      <visual name="visual">
        <geometry><cylinder><radius>0.04</radius><length>0.02</length></cylinder></geometry>
        <material>
          <ambient>0.0 0.29 0.46 1</ambient>
          <diffuse>0.0 0.29 0.46 1</diffuse>
          <specular>0.0 0.0 0.0 1</specular>
        </material>
      </visual>
      <collision name="collision">
        <geometry><cylinder><radius>0.04</radius><length>0.02</length></cylinder></geometry>
      </collision>
    </link>

    <link name="left_rear_wheel">
      <pose relative_to="chassis">-0.06 0.06 0 -1.5707 0 0</pose>
      <inertial>
        <mass>0.2</mass>
        <inertia>
          <ixx>0.000800</ixx><ixy>0</ixy><ixz>0</ixz>
          <iyy>0.000433</iyy><iyz>0</iyz><izz>0.000433</izz>
        </inertia>
      </inertial>
      <visual name="visual">
        <geometry><cylinder><radius>0.04</radius><length>0.02</length></cylinder></geometry>
        <material>
          <ambient>0.0 0.29 0.46 1</ambient>
          <diffuse>0.0 0.29 0.46 1</diffuse>
          <specular>0.0 0.0 0.0 1</specular>
        </material>
      </visual>
      <collision name="collision">
        <geometry><cylinder><radius>0.04</radius><length>0.02</length></cylinder></geometry>
      </collision>
    </link>

    <link name="right_front_wheel">
      <pose relative_to="chassis">0.06 -0.06 0 -1.5707 0 0</pose>
      <inertial>
        <mass>0.2</mass>
        <inertia>
          <ixx>0.000800</ixx><ixy>0</ixy><ixz>0</ixz>
          <iyy>0.000433</iyy><iyz>0</iyz><izz>0.000433</izz>
        </inertia>
      </inertial>
      <visual name="visual">
        <geometry><cylinder><radius>0.04</radius><length>0.02</length></cylinder></geometry>
        <material>
          <ambient>0.0 0.29 0.46 1</ambient>
          <diffuse>0.0 0.29 0.46 1</diffuse>
          <specular>0.0 0.0 0.0 1</specular>
        </material>
      </visual>
      <collision name="collision">
        <geometry><cylinder><radius>0.04</radius><length>0.02</length></cylinder></geometry>
      </collision>
    </link>

    <link name="right_rear_wheel">
      <pose relative_to="chassis">-0.06 -0.06 0 -1.5707 0 0</pose>
      <inertial>
        <mass>0.2</mass>
        <inertia>
          <ixx>0.000800</ixx><ixy>0</ixy><ixz>0</ixz>
          <iyy>0.000433</iyy><iyz>0</iyz><izz>0.000433</izz>
        </inertia>
      </inertial>
      <visual name="visual">
        <geometry><cylinder><radius>0.04</radius><length>0.02</length></cylinder></geometry>
        <material>
          <ambient>0.0 0.29 0.46 1</ambient>
          <diffuse>0.0 0.29 0.46 1</diffuse>
          <specular>0.0 0.0 0.0 1</specular>
        </material>
      </visual>
      <collision name="collision">
        <geometry><cylinder><radius>0.04</radius><length>0.02</length></cylinder></geometry>
      </collision>
    </link>

    <joint name="left_front_wheel_joint" type="revolute">
      <pose relative_to="left_front_wheel"/>
      <parent>chassis</parent>
      <child>left_front_wheel</child>
      <axis>
        <xyz expressed_in="__model__">0 1 0</xyz>
        <limit><lower>-1.79769e+308</lower><upper>1.79769e+308</upper></limit>
      </axis>
    </joint>

    <joint name="left_rear_wheel_joint" type="revolute">
      <pose relative_to="left_rear_wheel"/>
      <parent>chassis</parent>
      <child>left_rear_wheel</child>
      <axis>
        <xyz expressed_in="__model__">0 1 0</xyz>
        <limit><lower>-1.79769e+308</lower><upper>1.79769e+308</upper></limit>
      </axis>
    </joint>

    <joint name="right_front_wheel_joint" type="revolute">
      <pose relative_to="right_front_wheel"/>
      <parent>chassis</parent>
      <child>right_front_wheel</child>
      <axis>
        <xyz expressed_in="__model__">0 1 0</xyz>
        <limit><lower>-1.79769e+308</lower><upper>1.79769e+308</upper></limit>
      </axis>
    </joint>

    <joint name="right_rear_wheel_joint" type="revolute">
      <pose relative_to="right_rear_wheel"/>
      <parent>chassis</parent>
      <child>right_rear_wheel</child>
      <axis>
        <xyz expressed_in="__model__">0 1 0</xyz>
        <limit><lower>-1.79769e+308</lower><upper>1.79769e+308</upper></limit>
      </axis>
    </joint>

    <plugin filename="libignition-gazebo-diff-drive-system.so"
            name="ignition::gazebo::systems::DiffDrive">
      <left_joint>left_front_wheel_joint</left_joint>
      <left_joint>left_rear_wheel_joint</left_joint>
      <right_joint>right_front_wheel_joint</right_joint>
      <right_joint>right_rear_wheel_joint</right_joint>
      <wheel_separation>0.12</wheel_separation>
      <wheel_radius>0.04</wheel_radius>
      <odom_publish_frequency>10</odom_publish_frequency>
      <topic>cmd_vel</topic>
    </plugin>

    <!-- ===================== Virtual camera (3 cm, -60°) ================= -->
    <link name="camera_link">
      <!-- Pose du link à zéro : la pose réelle est portée par le joint fixe -->
      <pose>0 0 0 0 0 0</pose>
      <!-- petite inertie pour stabilité -->
      <inertial>
        <mass>0.05</mass>
        <inertia>
          <ixx>1.0e-4</ixx><ixy>0</ixy><ixz>0</ixz>
          <iyy>1.0e-4</iyy><iyz>0</iyz><izz>1.0e-4</izz>
        </inertia>
      </inertial>
      <visual name="camera_body">
        <geometry><box><size>0.03 0.03 0.02</size></box></geometry>
        <material>
          <ambient>0.1 0.1 0.1 1</ambient>
          <diffuse>0.2 0.2 0.2 1</diffuse>
          <specular>0 0 0 1</specular>
        </material>
      </visual>

      <sensor name="sim_cam" type="camera">
        <update_rate>30</update_rate>
        <always_on>true</always_on>
        <visualize>true</visualize>
        <camera>
          <horizontal_fov>1.0472</horizontal_fov> <!-- ~60° -->
          <image><width>640</width><height>480</height><format>RGB_INT8</format></image>
          <clip><near>0.01</near><far>50.0</far></clip>
        </camera>
        <topic>/sim/camera/image</topic>
      </sensor>
    </link>

    <!-- Joint fixe : place la caméra à z=0.03 m du châssis, pitch = -60° -->
    <joint name="camera_joint" type="fixed">
      <parent>chassis</parent>
      <child>camera_link</child>
      <!-- x y z roll pitch yaw -->
      <pose relative_to="chassis">0 0 0.03 0 -1.0472 0</pose>
    </joint>

    <!-- Frame optique (REP-103) pour RViz "Camera" -->
    <frame name="camera_optical_frame" attached_to="camera_link">
      <pose>0 0 0 -1.5708 0 -1.5708</pose>
    </frame>
    <!-- =================================================================== -->

  </model>
</sdf>
