<?xml version="1.0" ?>
<sdf version="1.9">
  <model name="simple_robot" canonical_link="chassis">
    <pose>0 0 0 0 0 0</pose>

    <link name="chassis">
      <pose relative_to="__model__">0.05 0 0.04 0 0 0</pose>
      <inertial>
        <mass>4.5</mass>
        <inertia>
          <ixx>0.001191615</ixx><ixy>0</ixy><ixz>0</ixz>
          <iyy>0.004051490</iyy><iyz>0</iyz><izz>0.004766458</izz>
        </inertia>
      </inertial>
      <visual name="visual">
        <geometry><box><size>0.2 0.1 0.05</size></box></geometry>
        <material>
          <ambient>0.0 0.612 0.867 1</ambient>
          <diffuse>0.0 0.612 0.867 1</diffuse>
          <specular>0.0 0.612 0.867 1</specular>
        </material>
      </visual>

      <visual name="aruco_tag"> 
        <!-- z augmenté pour qu'il soit au-dessus du châssis -->
        <pose>0 0 0.0255 0 0 0</pose>
        <cast_shadows>false</cast_shadows>
        <geometry>
          <plane>
            <size>0.04 0.04</size>
            <normal>0 0 1</normal>
            <texture>
              <size>0.03 0.03</size>
            </texture>
          </plane>
        </geometry>
        <material>
          <diffuse>1 1 1 1</diffuse>
          <pbr>
            <metal>
              <albedo_map>file://models/simple_robot/Aruco3.png</albedo_map>
            </metal>
          </pbr>
          <double_sided>true</double_sided>
        </material>
      </visual>

      <collision name="collision">
        <geometry><box><size>0.2 0.1 0.05</size></box></geometry>
      </collision>
    </link>

    <link name="left_front_wheel">
      <pose relative_to="chassis">0.06 0.06 0 -1.5707 0 0</pose>
      <inertial>
        <mass>0.2</mass>
        <inertia>
          <ixx>0.000800</ixx><ixy>0</ixy><ixz>0</ixz>
          <iyy>0.000433</iyy><iyz>0</iyz><izz>0.000433</izz>
        </inertia>
      </inertial>
      <visual name="visual">
        <geometry><cylinder><radius>0.04</radius><length>0.02</length></cylinder></geometry>
        <material>
          <ambient>0.0 0.29 0.46 1</ambient>
          <diffuse>0.0 0.29 0.46 1</diffuse>
          <specular>0.0 0.0 0.0 1</specular>
        </material>
      </visual>
      <collision name="collision">
        <geometry><cylinder><radius>0.04</radius><length>0.02</length></cylinder></geometry>
        <surface>
          <friction>
            <ode>
              <mu>1.0</mu>
              <mu2>1.0</mu2>
            </ode>
          </friction>
        </surface>
      </collision>
    </link>

    <link name="left_rear_wheel">
      <pose relative_to="chassis">-0.06 0.06 0 -1.5707 0 0</pose>
      <inertial>
        <mass>0.2</mass>
        <inertia>
          <ixx>0.000800</ixx><ixy>0</ixy><ixz>0</ixz>
          <iyy>0.000433</iyy><iyz>0</iyz><izz>0.000433</izz>
        </inertia>
      </inertial>
      <visual name="visual">
        <geometry><cylinder><radius>0.04</radius><length>0.02</length></cylinder></geometry>
        <material>
          <ambient>0.0 0.29 0.46 1</ambient>
          <diffuse>0.0 0.29 0.46 1</diffuse>
          <specular>0.0 0.0 0.0 1</specular>
        </material>
      </visual>
      <collision name="collision">
        <geometry><cylinder><radius>0.04</radius><length>0.02</length></cylinder></geometry>
        <surface>
          <friction>
            <ode>
              <mu>1.0</mu>
              <mu2>1.0</mu2>
            </ode>
          </friction>
        </surface>
      </collision>
    </link>

    <link name="right_front_wheel">
      <pose relative_to="chassis">0.06 -0.06 0 -1.5707 0 0</pose>
      <inertial>
        <mass>0.2</mass>
        <inertia>
          <ixx>0.000800</ixx><ixy>0</ixy><ixz>0</ixz>
          <iyy>0.000433</iyy><iyz>0</iyz><izz>0.000433</izz>
        </inertia>
      </inertial>
      <visual name="visual">
        <geometry><cylinder><radius>0.04</radius><length>0.02</length></cylinder></geometry>
        <material>
          <ambient>0.0 0.29 0.46 1</ambient>
          <diffuse>0.0 0.29 0.46 1</diffuse>
          <specular>0.0 0.0 0.0 1</specular>
        </material>
      </visual>
      <collision name="collision">
        <geometry><cylinder><radius>0.04</radius><length>0.02</length></cylinder></geometry>
        <surface>
          <friction>
            <ode>
              <mu>1.0</mu>
              <mu2>1.0</mu2>
            </ode>
          </friction>
        </surface>
      </collision>
    </link>

    <link name="right_rear_wheel">
      <pose relative_to="chassis">-0.06 -0.06 0 -1.5707 0 0</pose>
      <inertial>
        <mass>0.2</mass>
        <inertia>
          <ixx>0.000800</ixx><ixy>0</ixy><ixz>0</ixz>
          <iyy>0.000433</iyy><iyz>0</iyz><izz>0.000433</izz>
        </inertia>
      </inertial>
      <visual name="visual">
        <geometry><cylinder><radius>0.04</radius><length>0.02</length></cylinder></geometry>
        <material>
          <ambient>0.0 0.29 0.46 1</ambient>
          <diffuse>0.0 0.29 0.46 1</diffuse>
          <specular>0.0 0.0 0.0 1</specular>
        </material>
      </visual>
      <collision name="collision">
        <geometry><cylinder><radius>0.04</radius><length>0.02</length></cylinder></geometry>
        <surface>
          <friction>
            <ode>
              <mu>1.0</mu>
              <mu2>1.0</mu2>
            </ode>
          </friction>
        </surface>
      </collision>
    </link>

    <joint name="left_front_wheel_joint" type="revolute">
      <pose relative_to="left_front_wheel"/>
      <parent>chassis</parent>
      <child>left_front_wheel</child>
      <axis>
        <xyz expressed_in="__model__">0 1 0</xyz>
        <limit><lower>-1.79769e+308</lower><upper>1.79769e+308</upper></limit>
      </axis>
    </joint>

    <joint name="left_rear_wheel_joint" type="revolute">
      <pose relative_to="left_rear_wheel"/>
      <parent>chassis</parent>
      <child>left_rear_wheel</child>
      <axis>
        <xyz expressed_in="__model__">0 1 0</xyz>
        <limit><lower>-1.79769e+308</lower><upper>1.79769e+308</upper></limit>
      </axis>
    </joint>

    <joint name="right_front_wheel_joint" type="revolute">
      <pose relative_to="right_front_wheel"/>
      <parent>chassis</parent>
      <child>right_front_wheel</child>
      <axis>
        <xyz expressed_in="__model__">0 1 0</xyz>
        <limit><lower>-1.79769e+308</lower><upper>1.79769e+308</upper></limit>
      </axis>
    </joint>

    <joint name="right_rear_wheel_joint" type="revolute">
      <pose relative_to="right_rear_wheel"/>
      <parent>chassis</parent>
      <child>right_rear_wheel</child>
      <axis>
        <xyz expressed_in="__model__">0 1 0</xyz>
        <limit><lower>-1.79769e+308</lower><upper>1.79769e+308</upper></limit>
      </axis>
    </joint>

    <plugin filename="libignition-gazebo-diff-drive-system.so"
            name="ignition::gazebo::systems::DiffDrive">
      <left_joint>left_front_wheel_joint</left_joint>
      <left_joint>left_rear_wheel_joint</left_joint>
      <right_joint>right_front_wheel_joint</right_joint>
      <right_joint>right_rear_wheel_joint</right_joint>
      <wheel_separation>0.12</wheel_separation>
      <wheel_radius>0.04</wheel_radius>
      <odom_publish_frequency>50</odom_publish_frequency>
      <topic>/cmd_vel</topic>
    </plugin>

    <plugin filename="libignition-gazebo-joint-state-publisher-system.so"
            name="ignition::gazebo::systems::JointStatePublisher">
      <update_rate>10</update_rate>
      <topic>/joint_states</topic>
    </plugin>

    <plugin filename="libignition-gazebo-pose-publisher-system.so"
            name="ignition::gazebo::systems::PosePublisher">
      <publish_link_pose>true</publish_link_pose>
      <publish_sensor_pose>true</publish_sensor_pose>
      <publish_collision_pose>false</publish_collision_pose>
      <publish_visual_pose>false</publish_visual_pose>
      <publish_nested_model_pose>true</publish_nested_model_pose>
      <use_pose_vector_msg>true</use_pose_vector_msg>
      <static_publisher>false</static_publisher>
      <static_update_frequency>10</static_update_frequency>
    </plugin>

    <link name="camera_link">
      <pose relative_to="chassis">0.085 0 0.04 0 0 0</pose>
      <inertial>
        <mass>0.01</mass>
        <inertia>
          <ixx>1e-6</ixx><iyy>1e-6</iyy><izz>1e-6</izz>
          <ixy>0</ixy><ixz>0</ixz><iyz>0</iyz>
        </inertia>
      </inertial>

      <visual name="camera_visual">
        <pose>0 0 0 0 0 0</pose>
        <geometry><box><size>0.03 0.03 0.03</size></box></geometry>
        <material>
          <ambient>0 0 0 1</ambient>
          <diffuse>0.2 0.2 0.2 1</diffuse>
        </material>
      </visual>

      <sensor name="camera_sensor" type="camera">
        <pose>0 0 0 0 0.5236 0</pose>
        <always_on>true</always_on>
        <update_rate>30</update_rate>
        <visualize>true</visualize>
        <camera>
          <horizontal_fov>1.78</horizontal_fov>
          <image>
            <width>640</width>
            <height>480</height>
            <format>RGB_INT8</format>
          </image>
          <clip><near>0.1</near><far>100</far></clip>
        </camera>
        <topic>camera/image_raw</topic>
      </sensor>
    </link>

    <joint name="camera_joint" type="fixed">
      <parent>chassis</parent>
      <child>camera_link</child>
      <pose relative_to="chassis">0 0 0 0 0 0</pose>
    </joint>

    <!-- LiDAR -->
    <link name="base_scan">
      <!-- position du boîtier LiDAR par rapport au modèle -->
      <pose relative_to="chassis">0 0 0.10 0 0 0</pose>

      <inertial>
        <mass>0.05</mass>
        <inertia>
          <ixx>1.0e-5</ixx><iyy>1.0e-5</iyy><izz>1.0e-5</izz>
          <ixy>0</ixy><ixz>0</ixz><iyz>0</iyz>
        </inertia>
      </inertial>

      <!-- VISUAL: cylindre Ø36mm x 13mm -->
      <visual name="lidar_visual">
        <pose>0 0 0 0 0 0</pose>
        <geometry>
          <cylinder>
            <radius>0.018</radius>
            <length>0.013</length>
          </cylinder>
        </geometry>
        <material>
          <ambient>0.1 0.1 0.1 1</ambient>
          <diffuse>0.2 0.2 0.2 1</diffuse>
        </material>
      </visual>

      <!-- COLLISION (même géométrie) -->
      <collision name="lidar_collision">
        <geometry>
          <cylinder>
            <radius>0.018</radius>
            <length>0.013</length>
          </cylinder>
        </geometry>
      </collision>

      <!-- Capteur LiDAR (ray) côté GZ -->
      <sensor name="hls_lfcd_lds" type="gpu_lidar">
        <pose>0 0 0.010 0 0 0</pose>
        <always_on>1</always_on>
        <update_rate>20</update_rate>
        <visualize>true</visualize>
        <topic>/lidar</topic>
        <gz_frame_id>simple_robot/base_scan/hls_lfcd_lds</gz_frame_id>
        <ray>
          <scan>
            <horizontal>
              <samples>360</samples>
              <resolution>1</resolution>
              <min_angle>-3.14159</min_angle>
              <max_angle>3.14159</max_angle>
            </horizontal>
            <vertical>
              <samples>1</samples>
              <resolution>1</resolution>
              <min_angle>0</min_angle>
              <max_angle>0</max_angle>
            </vertical>
          </scan>
          <range>
            <min>0.12</min>
            <max>6.0</max>
            <resolution>0.01</resolution>
          </range>
          <noise>
            <type>gaussian</type>
            <mean>0.0</mean>
            <stddev>0.01</stddev>
          </noise>
        </ray>
      </sensor>
    </link>

    <joint name="lidar_joint" type="fixed">
      <parent>chassis</parent>
      <child>base_scan</child>
      <pose relative_to="chassis">0 0 0 0 0 0</pose>
    </joint>

  </model>
</sdf>